<?xml version="1.0" encoding="UTF-8"?>
<!-- Generated by org.testng.reporters.JUnitReportReporter -->
<testsuite skipped="0" hostname="KARMA" name="org.expectedexception.ExpectedExceptionMessageDemo" tests="3" failures="0" timestamp="2020-12-27T17:34:56 CST" time="0.093" errors="1">
  <testcase name="exceptionMessageTwoTest" time="0.004" classname="org.expectedexception.ExpectedExceptionMessageDemo"/>
  <system-out/>
  <testcase name="exceptionMessageOneTest" time="0.087" classname="org.expectedexception.ExpectedExceptionMessageDemo"/>
  <system-out/>
  <testcase name="exceptionMessageThreeTest" time="0.002" classname="org.expectedexception.ExpectedExceptionMessageDemo">
    <error type="org.testng.TestException" message="
The exception was thrown with the wrong message: expected &quot;Pass Message test&quot; but got &quot;Fail Message test&quot;">
      <![CDATA[org.testng.TestException: 
The exception was thrown with the wrong message: expected "Pass Message test" but got "Fail Message test"
at org.testng.internal.ExpectedExceptionsHolder.wrongException(ExpectedExceptionsHolder.java:70)
at org.testng.internal.TestInvoker.considerExceptions(TestInvoker.java:737)
at org.testng.internal.TestInvoker.invokeMethod(TestInvoker.java:635)
at org.testng.internal.TestInvoker.invokeTestMethod(TestInvoker.java:174)
at org.testng.internal.MethodRunner.runInSequence(MethodRunner.java:46)
at org.testng.internal.TestInvoker$MethodInvocationAgent.invoke(TestInvoker.java:822)
at org.testng.internal.TestInvoker.invokeTestMethods(TestInvoker.java:147)
at org.testng.internal.TestMethodWorker.invokeTestMethods(TestMethodWorker.java:146)
at org.testng.internal.TestMethodWorker.run(TestMethodWorker.java:128)
at java.util.ArrayList.forEach(Unknown Source)
at org.testng.TestRunner.privateRun(TestRunner.java:764)
at org.testng.TestRunner.run(TestRunner.java:585)
at org.testng.SuiteRunner.runTest(SuiteRunner.java:384)
at org.testng.SuiteRunner.runSequentially(SuiteRunner.java:378)
at org.testng.SuiteRunner.privateRun(SuiteRunner.java:337)
at org.testng.SuiteRunner.run(SuiteRunner.java:286)
at org.testng.SuiteRunnerWorker.runSuite(SuiteRunnerWorker.java:53)
at org.testng.SuiteRunnerWorker.run(SuiteRunnerWorker.java:96)
at org.testng.TestNG.runSuitesSequentially(TestNG.java:1218)
at org.testng.TestNG.runSuitesLocally(TestNG.java:1140)
at org.testng.TestNG.runSuites(TestNG.java:1069)
at org.testng.TestNG.run(TestNG.java:1037)
at org.testng.remote.AbstractRemoteTestNG.run(AbstractRemoteTestNG.java:115)
at org.testng.remote.RemoteTestNG.initAndRun(RemoteTestNG.java:251)
at org.testng.remote.RemoteTestNG.main(RemoteTestNG.java:77)
Caused by: java.io.IOException: Fail Message test
at org.expectedexception.ExpectedExceptionMessageDemo.exceptionMessageThreeTest(ExpectedExceptionMessageDemo.java:25)
at sun.reflect.NativeMethodAccessorImpl.invoke0(Native Method)
at sun.reflect.NativeMethodAccessorImpl.invoke(Unknown Source)
at sun.reflect.DelegatingMethodAccessorImpl.invoke(Unknown Source)
at java.lang.reflect.Method.invoke(Unknown Source)
at org.testng.internal.MethodInvocationHelper.invokeMethod(MethodInvocationHelper.java:132)
at org.testng.internal.TestInvoker.invokeMethod(TestInvoker.java:599)
... 22 more
]]>
    </error>
  </testcase> <!-- exceptionMessageThreeTest -->
  <system-out/>
</testsuite> <!-- org.expectedexception.ExpectedExceptionMessageDemo -->
